<?xml version='1.0' encoding='utf-8'?>
<mujoco model="TH02-A7-torque">
  <compiler angle="radian" meshdir="./meshes" eulerseq="xyz" />
  <option timestep="0.001" gravity="0 0 -9.81" />
  <visual>
    <headlight ambient="0.3 0.3 0.3" diffuse="0.4 0.4 0.4" specular="0.1 0.1 0.1" />
    <rgba haze="0.15 0.25 0.35 1" />
    <global offwidth="1920" offheight="1080" />
  </visual>
  <asset>
    <texture name="grid" type="2d" builtin="checker" rgb1="0.2 0.3 0.4" rgb2="0.3 0.4 0.5" width="512" height="512" mark="edge" markrgb="0.2 0.3 0.4" />
    <material name="grid" texture="grid" texrepeat="1 1" texuniform="true" reflectance="0.2" />
    <texture name="skybox" type="skybox" builtin="gradient" rgb1="0.6 0.7 0.8" rgb2="0.4 0.5 0.7" width="512" height="512" />
  </asset>
  <asset>
    <mesh name="ANKLE_L" file="ANKLE_L.STL" />
    <mesh name="ANKLE_R" file="ANKLE_R.STL" />
    <mesh name="BASE_LINK" file="BASE_LINK.STL" />
    <mesh name="ELBOW_L" file="ELBOW_L.STL" />
    <mesh name="ELBOW_R" file="ELBOW_R.STL" />
    <mesh name="FEMUR_L" file="FEMUR_L.STL" />
    <mesh name="FEMUR_R" file="FEMUR_R.STL" />
    <mesh name="FOOT_L" file="FOOT_L.STL" />
    <mesh name="FOOT_R" file="FOOT_R.STL" />
    <mesh name="FOREARM_L" file="FOREARM_L.STL" />
    <mesh name="FOREARM_R" file="FOREARM_R.STL" />
    <mesh name="HEAD" file="HEAD.STL" />
    <mesh name="HIP_ABAD_L" file="HIP_ABAD_L.STL" />
    <mesh name="HIP_ABAD_R" file="HIP_ABAD_R.STL" />
    <mesh name="HIP_L" file="HIP_L.STL" />
    <mesh name="HIP_R" file="HIP_R.STL" />
    <mesh name="LOWERSHOULDER_L" file="LOWERSHOULDER_L.STL" />
    <mesh name="LOWERSHOULDER_R" file="LOWERSHOULDER_R.STL" />
    <mesh name="LOWERWRIST_L" file="LOWERWRIST_L.STL" />
    <mesh name="LOWERWRIST_R" file="LOWERWRIST_R.STL" />
    <mesh name="NECK" file="NECK.STL" />
    <mesh name="TIBIA_L" file="TIBIA_L.STL" />
    <mesh name="TIBIA_R" file="TIBIA_R.STL" />
    <mesh name="UPPERARM_L" file="UPPERARM_L.STL" />
    <mesh name="UPPERARM_R" file="UPPERARM_R.STL" />
    <mesh name="UPPERSHOULDER_L" file="UPPERSHOULDER_L.STL" />
    <mesh name="UPPERSHOULDER_R" file="UPPERSHOULDER_R.STL" />
    <mesh name="UPPERWRIST_L" file="UPPERWRIST_L.STL" />
    <mesh name="UPPERWRIST_R" file="UPPERWRIST_R.STL" />
  </asset>
  <worldbody>
    <light name="light1" mode="fixed" pos="2 2 4" dir="-0.5 -0.5 -1" diffuse="0.4 0.4 0.4" specular="0.2 0.2 0.2" castshadow="false" />
    <light name="light2" mode="fixed" pos="-2 2 3" dir="0.5 -0.5 -1" diffuse="0.3 0.3 0.3" specular="0.15 0.15 0.15" castshadow="false" />
    <light name="light3" mode="fixed" pos="0 -3 3" dir="0 1 -1" diffuse="0.25 0.25 0.25" specular="0.1 0.1 0.1" castshadow="false" />
    <geom name="floor" type="plane" size="20 20 0.1" rgba="0.95 0.95 0.95 1" material="grid" condim="3" />
    <body name="BASE_LINK" pos="0 0 1.3">
      <geom type="mesh" mesh="BASE_LINK" contype="0" conaffinity="0" group="1" />
      <body name="HIP_R" pos="-0.18337794 -0.0625 -0.28837794" quat="0.9238795325873352 0.0 0.3826834321814926 0.0">
        <joint name="HIP_YAW_R" type="hinge" axis="0 0 1" range="-3.14 3.14" damping="0.2" />
        <inertial pos="0.00398 -0.00006 0.00636" mass="0.83264" diaginertia="0.0019 0.00124 0.00094" />
        <geom type="mesh" mesh="HIP_R" rgba="0.792156863 0.819607843 0.933333333 1" contype="0" conaffinity="0" group="1" />
        <body name="HIP_ABAD_R" pos="0.141 0 0" quat="0.4999999998974482 0.5 -0.5000000001025517 -0.5">
          <joint name="HIP_ROLL_R" type="hinge" axis="0 0 -1" range="-3.14 3.14" damping="0.2" />
          <inertial pos="-0.002 0.00147 0.00404" mass="2.78794" fullinertia="0.01442 0.00791 0.0072 0.0 -2e-05 0.0" />
          <geom type="mesh" mesh="HIP_ABAD_R" rgba="0.792156863 0.819607843 0.933333333 1" contype="0" conaffinity="0" group="1" />
          <body name="FEMUR_R" pos="0.029 0 0" quat="0.6532814823289134 -0.27059805020292127 0.6532814824399145 -0.2705980502029213">
            <joint name="HIP_PITCH_R" type="hinge" axis="0 0 -1" range="-3.14 3.14" damping="0.2" />
            <inertial pos="0.06111 0.00174 0.02002" mass="3.75384" fullinertia="0.01172 0.07026 0.07594 0.00157 0.00098 0.00014" />
            <geom type="mesh" mesh="FEMUR_R" rgba="0.792156863 0.819607843 0.933333333 1" contype="0" conaffinity="0" group="1" />
            <body name="TIBIA_R" pos="0.375 0 0">
              <joint name="KNEE_PITCH_R" type="hinge" axis="0 0 -1" range="-3.14 3.14" damping="0.2" />
              <inertial pos="0.09678 0.00694 -0.00006" mass="1.27716" fullinertia="0.00091 0.02323 0.02318 0.00069 -1e-05 0.0" />
              <geom type="mesh" mesh="TIBIA_R" rgba="0.792156863 0.819607843 0.933333333 1" contype="0" conaffinity="0" group="1" />
              <body name="ANKLE_R" pos="0.375 0 0">
                <joint name="ANKLE_PITCH_R" type="hinge" axis="0 0 -1" range="-3.14 3.14" damping="1.0" />
                <inertial pos="0 0 0" mass="0.006946" diaginertia="1e-04 1e-04 1e-04" />
                <geom type="mesh" mesh="ANKLE_R" rgba="0.792156863 0.819607843 0.933333333 1" contype="0" conaffinity="0" group="1" />
                <body name="FOOT_R" pos="0 0 0" quat="0.7071067811140325 -0.7071067812590626 0.0 0.0">
                  <joint name="ANKLE_ROLL_R" type="hinge" axis="0 0 1" range="-3.14 3.14" damping="0.2" />
                  <inertial pos="0.0337 5.00E-05 0.04684" mass="0.41628" fullinertia="0.002594 0.002998 0.000722 9.89e-07 0.000725 1.24e-06" />
                  <geom type="mesh" mesh="FOOT_R" rgba="0.792156863 0.819607843 0.933333333 1" contype="0" conaffinity="0" group="1" />
                  <!-- <geom name="FOOT_R_heel_in" type="sphere" size="0.015" pos="-0.05 0.06 0.08" rgba="0.9 0.1 0.1 0.5" contype="1" conaffinity="1" condim="3" friction="1.0 0.005 0.0001" />
                  <geom name="FOOT_R_heel_out" type="sphere" size="0.015" pos="-0.05 -0.06 0.08" rgba="0.9 0.1 0.1 0.5" contype="1" conaffinity="1" condim="3" friction="1.0 0.005 0.0001" />
                  <geom name="FOOT_R_toe_in" type="sphere" size="0.015" pos="0.12 0.06 0.08" rgba="0.9 0.1 0.1 0.5" contype="1" conaffinity="1" condim="3" friction="1.0 0.005 0.0001" />
                  <geom name="FOOT_R_toe_out" type="sphere" size="0.015" pos="0.12 -0.06 0.08" rgba="0.9 0.1 0.1 0.5" contype="1" conaffinity="1" condim="3" friction="1.0 0.005 0.0001" /> -->
                </body>
              </body>
            </body>
          </body>
        </body>
      </body>
      <body name="HIP_L" pos="-0.18337794 0.0625 -0.28837794" quat="0.9238795325873352 0.0 0.3826834321814926 0.0">
        <joint name="HIP_YAW_L" type="hinge" axis="0 0 1" range="-3.14 3.14" damping="0.2" />
        <inertial pos="0.00398 -0.00006 0.00636" mass="0.83264" diaginertia="0.0019 0.00124 0.00094" />
        <geom type="mesh" mesh="HIP_L" rgba="0.792156863 0.819607843 0.933333333 1" contype="0" conaffinity="0" group="1" />
        <body name="HIP_ABAD_L" pos="0.141 0 0" quat="0.4999999998974482 0.5 -0.5000000001025517 -0.5">
          <joint name="HIP_ROLL_L" type="hinge" axis="0 0 -1" range="-3.14 3.14" damping="0.2" />
          <inertial pos="0.00198 0.00146 0.00395" mass="2.818" fullinertia="0.01442 0.00791 0.0072 0.0 2e-05 0.0" />
          <geom type="mesh" mesh="HIP_ABAD_L" rgba="0.792156863 0.819607843 0.933333333 1" contype="0" conaffinity="0" group="1" />
          <body name="FEMUR_L" pos="-0.029 0 0" quat="0.6532814823289134 -0.27059805020292127 0.6532814824399145 -0.2705980502029213">
            <joint name="HIP_PITCH_L" type="hinge" axis="0 0 -1" range="-3.14 3.14" damping="0.2" />
            <inertial pos="0.06112 0.00177 -0.02002" mass="3.75393" fullinertia="0.01172 0.07027 0.07595 0.00157 -0.00098 -0.00014" />
            <geom type="mesh" mesh="FEMUR_L" rgba="0.792156863 0.819607843 0.933333333 1" contype="0" conaffinity="0" group="1" />
            <body name="TIBIA_L" pos="0.375 0 0">
              <joint name="KNEE_PITCH_L" type="hinge" axis="0 0 -1" range="-3.14 3.14" damping="0.2" />
              <inertial pos="0.09678 0.00694 -0.00006" mass="1.27716" fullinertia="0.00091 0.02323 0.02318 0.00069 -1e-05 0.0" />
              <geom type="mesh" mesh="TIBIA_L" rgba="0.792156863 0.819607843 0.933333333 1" contype="0" conaffinity="0" group="1" />
              <body name="ANKLE_L" pos="0.375 0 0">
                <joint name="ANKLE_PITCH_L" type="hinge" axis="0 0 -1" range="-3.14 3.14" damping="1.0" />
                <inertial pos="0 0 0" mass="0.006946" diaginertia="1e-04 1e-04 1e-04" />
                <geom type="mesh" mesh="ANKLE_L" rgba="0.792156863 0.819607843 0.933333333 1" contype="0" conaffinity="0" group="1" />
                <body name="FOOT_L" pos="0 0 0" quat="0.7071067811140325 -0.7071067812590626 0.0 0.0">
                  <joint name="ANKLE_ROLL_L" type="hinge" axis="0 0 1" range="-3.14 3.14" damping="0.2" />
                  <inertial pos="0.0337 5.00E-05 0.04684" mass="0.41628" fullinertia="0.002594 0.002998 0.000722 9.89e-07 0.000725 1.24e-06" />
                  <geom type="mesh" mesh="FOOT_L" rgba="0.792156863 0.819607843 0.933333333 1" contype="0" conaffinity="0" group="1" />
                  <!-- <geom name="FOOT_L_heel_in" type="sphere" size="0.015" pos="-0.05 0.06 0.08" rgba="0.9 0.1 0.1 0.5" contype="1" conaffinity="1" condim="3" friction="1.0 0.005 0.0001" />
                  <geom name="FOOT_L_heel_out" type="sphere" size="0.015" pos="-0.05 -0.06 0.08" rgba="0.9 0.1 0.1 0.5" contype="1" conaffinity="1" condim="3" friction="1.0 0.005 0.0001" />
                  <geom name="FOOT_L_toe_in" type="sphere" size="0.015" pos="0.12 0.06 0.08" rgba="0.9 0.1 0.1 0.5" contype="1" conaffinity="1" condim="3" friction="1.0 0.005 0.0001" />
                  <geom name="FOOT_L_toe_out" type="sphere" size="0.015" pos="0.12 -0.06 0.08" rgba="0.9 0.1 0.1 0.5" contype="1" conaffinity="1" condim="3" friction="1.0 0.005 0.0001" /> -->
                </body>
              </body>
            </body>
          </body>
        </body>
      </body>
      <body name="UPPERSHOULDER_R" pos="-0.065084608 -0.1567 0.113474882" quat="0.707 0.707 0 0">
        <joint name="SHOULDER_PITCH_R" type="hinge" axis="0 0 -1" range="-3.14 3.14" damping="0.5" />
        <inertial pos="0.00158 0.00121 -0.00674" mass="0.43611" fullinertia="0.000385927 0.000304132 0.000234707 -2.6e-07 9.81e-07 5.57e-06" />
        <geom type="mesh" mesh="UPPERSHOULDER_R" rgba="0.792156863 0.819607843 0.933333333 1" contype="0" conaffinity="0" group="1" />
        <body name="LOWERSHOULDER_R" pos="0 0 0" quat="2.0852339467722704e-10 0.7071067812590626 -2.0852339471999592e-10 0.7071067811140325">
          <joint name="SHOULDER_ROLL_R" type="hinge" axis="0 0 1" range="-3.14 3.14" damping="0.5" />
          <inertial pos="0.0535 -6.00E-05 2.00E-05" mass="0.35798" fullinertia="0.000261 0.001315 0.001242 -1.67e-06 2.5e-07 -1.55e-08" />
          <geom type="mesh" mesh="LOWERSHOULDER_R" rgba="0.792156863 0.819607843 0.933333333 1" contype="0" conaffinity="0" group="1" />
          <body name="UPPERARM_R" pos="0 0 0" quat="2.0852339467722704e-10 0.7071067812590626 -2.0852339471999592e-10 0.7071067811140325">
            <joint name="SHOULDER_YAW_R" type="hinge" axis="0 0 -1" range="-3.14 3.14" damping="0.5" />
            <inertial pos="-0.00152 -0.0104 0.1973" mass="0.51544" fullinertia="0.021671894 0.021508856 0.000365708 1.03e-05 -0.0001758 -0.001195001" />
            <geom type="mesh" mesh="UPPERARM_R" rgba="0.792156863 0.819607843 0.933333333 1" contype="0" conaffinity="0" group="1" />
            <body name="ELBOW_R" pos="0 -0.015 0.22495" quat="2.0852339467722704e-10 0.7071067812590626 -2.0852339471999592e-10 0.7071067811140325">
              <joint name="ELBOW_PITCH_R" type="hinge" axis="0 0 1" range="-3.14 3.14" damping="0.5" />
              <inertial pos="0.05387 -0.01441 1.00E-05" mass="0.37853" fullinertia="0.000368755 0.001430606 0.00143177 -0.000307924 -2.21e-07 -3.69e-07" />
              <geom type="mesh" mesh="ELBOW_R" rgba="0.792156863 0.819607843 0.933333333 1" contype="0" conaffinity="0" group="1" />
              <body name="FOREARM_R" pos="0.154950006 -0.015000026 0" quat="2.0852339467722704e-10 0.7071067812590626 -2.0852339471999592e-10 0.7071067811140325">
                <joint name="ELBOW_YAW_R" type="hinge" axis="0 0 -1" range="-3.14 3.14" damping="0.5" />
                <inertial pos="-0.00164 1.00E-05 -0.01407" mass="0.47694" fullinertia="0.000684321 0.000600813 0.000265071 -2.15e-07 4.7e-06 -1.32e-07" />
                <geom type="mesh" mesh="FOREARM_R" rgba="0.792156863 0.819607843 0.933333333 1" contype="0" conaffinity="0" group="1" />
                <body name="UPPERWRIST_R" pos="0 0 0" quat="2.0852339467722704e-10 0.7071067811140325 -2.0852339471999592e-10 0.7071067812590626">
                  <joint name="WRIST_PITCH_R" type="hinge" axis="0 0 1" range="-3.14 3.14" damping="0.2" />
                  <inertial pos="0.05463 -0.00013 9.00E-05" mass="0.37004" fullinertia="0.000277159 0.001412655 0.001337476 -3.87e-06 2.51e-06 5.51e-08" />
                  <geom type="mesh" mesh="UPPERWRIST_R" rgba="0.792156863 0.819607843 0.933333333 1" contype="0" conaffinity="0" group="1" />
                  <body name="LOWERWRIST_R" pos="0 0 0" quat="2.0852339467722704e-10 0.7071067811140325 -2.0852339471999592e-10 0.7071067812590626">
                    <joint name="WRIST_YAW_R" type="hinge" axis="0 0 -1" range="-3.14 3.14" damping="1" />
                    <inertial pos="0 2.42E-06 0.00010824" mass="0.42" diaginertia="1e-04 1e-04 1e-04" />
                    <geom type="mesh" mesh="LOWERWRIST_R" rgba="0.792156863 0.819607843 0.933333333 1" contype="0" conaffinity="0" group="1" />
                  </body>
                </body>
              </body>
            </body>
          </body>
        </body>
      </body>
      <body name="UPPERSHOULDER_L" pos="-0.065084608 0.1567 0.113474882" quat="0.7071067811140325 0.7071067812590626 0.0 0.0">
        <joint name="SHOULDER_PITCH_L" type="hinge" axis="0 0 -1" range="-3.14 3.14" damping="0.5" />
        <inertial pos="0.00158 0.00123 0.00673" mass="0.43611" fullinertia="0.000385927 0.000304104 0.000234735 -3.28e-07 -9.42e-07 -5.56e-06" />
        <geom type="mesh" mesh="UPPERSHOULDER_L" rgba="0.792156863 0.819607843 0.933333333 1" contype="0" conaffinity="0" group="1" />
        <body name="LOWERSHOULDER_L" pos="0 0 0" quat="0.7071067811140325 0.0 0.7071067812590626 0.0">
          <joint name="SHOULDER_ROLL_L" type="hinge" axis="0 0 1" range="-3.14 3.14" damping="0.5" />
          <inertial pos="0.0535 6.00E-05 -2.00E-05" mass="0.35798" fullinertia="0.000261 0.001315 0.001242 1.67e-06 -2.5e-07 -1.55e-08" />
          <geom type="mesh" mesh="LOWERSHOULDER_L" rgba="0.792156863 0.819607843 0.933333333 1" contype="0" conaffinity="0" group="1" />
          <body name="UPPERARM_L" pos="0 0 0" quat="2.0852339467722704e-10 0.7071067811140325 -2.0852339471999592e-10 0.7071067812590626">
            <joint name="SHOULDER_YAW_L" type="hinge" axis="0 0 1" range="-3.14 3.14" damping="0.5" />
            <inertial pos="-0.00152 0.01042 0.1973" mass="0.51544" fullinertia="0.021671007 0.021507692 0.000365985 -1.03e-05 -0.000175798 0.001197139" />
            <geom type="mesh" mesh="UPPERARM_L" rgba="0.792156863 0.819607843 0.933333333 1" contype="0" conaffinity="0" group="1" />
            <body name="ELBOW_L" pos="0 0.015 0.22495" quat="2.0852339467722704e-10 0.7071067811140325 -2.0852339471999592e-10 0.7071067812590626">
              <joint name="ELBOW_PITCH_L" type="hinge" axis="0 0 1" range="-3.14 3.14" damping="0.5" />
              <inertial pos="0.05387 0.01441 -1.00E-05" mass="0.37854" fullinertia="0.000368777 0.00143067 0.001431848 0.000307949 -5.93e-07 2.39e-07" />
              <geom type="mesh" mesh="ELBOW_L" rgba="0.792156863 0.819607843 0.933333333 1" contype="0" conaffinity="0" group="1" />
              <body name="FOREARM_L" pos="0.154950006 0.015 0" quat="8.98144374188884e-05 0.7071067807133624 -8.981443609009309e-05 0.7071067702517908">
                <joint name="ELBOW_YAW_L" type="hinge" axis="0 0 1" range="-3.14 3.14" damping="0.5" />
                <inertial pos="0.00164 2.00E-05 -0.01407" mass="0.47694" fullinertia="0.00068432 0.00060081 0.000265072 2.81e-07 -4.7e-06 -7.48e-07" />
                <geom type="mesh" mesh="FOREARM_L" rgba="0.792156863 0.819607843 0.933333333 1" contype="0" conaffinity="0" group="1" />
                <body name="UPPERWRIST_L" pos="0 0 0" quat="2.0852339467722704e-10 0.7071067811140325 -2.0852339471999592e-10 0.7071067812590626">
                  <joint name="WRIST_PITCH_L" type="hinge" axis="0 0 1" range="-3.14 3.14" damping="0.2" />
                  <inertial pos="0.05463 0.00013 7.00E-05" mass="0.37004" fullinertia="0.000277159 0.001412655 0.001337475 3.87e-06 2.13e-06 -5.78e-08" />
                  <geom type="mesh" mesh="UPPERWRIST_L" rgba="0.792156863 0.819607843 0.933333333 1" contype="0" conaffinity="0" group="1" />
                  <body name="LOWERWRIST_L" pos="0 0 0" quat="2.0852339467722704e-10 0.7071067811140325 -2.0852339471999592e-10 0.7071067812590626">
                    <joint name="WRIST_YAW_L" type="hinge" axis="0 0 1" range="-3.14 3.14" damping="1" />
                    <inertial pos="0 -2.37E-06 0.00010824" mass="0.42" diaginertia="1e-04 1e-04 1e-04" />
                    <geom type="mesh" mesh="LOWERWRIST_L" rgba="0.792156863 0.819607843 0.933333333 1" contype="0" conaffinity="0" group="1" />
                  </body>
                </body>
              </body>
            </body>
          </body>
        </body>
      </body>
      <body name="NECK" pos="-0.069373655 0 0.230835692">
        <joint name="HEAD_YAW" type="hinge" axis="0 0 1" range="-3.14 3.14" damping="0.2" />
        <inertial pos="0 0.00017 -0.00489" mass="0.34044" fullinertia="0.000199 0.000274 0.000167 1.56e-05 -2.91e-05 -2.51e-06" />
        <geom type="mesh" mesh="NECK" rgba="0.792156863 0.819607843 0.933333333 1" contype="0" conaffinity="0" group="1" />
        <body name="HEAD" pos="0 0 0" quat="0.7071067811140325 0.7071067812590626 0.0 0.0">
          <joint name="HEAD_PITCH" type="hinge" axis="0 0 1" range="-3.14 3.14" damping="0.2" />
          <inertial pos="0.00094 0.0631 -1.00E-05" mass="0.67367" fullinertia="0.004633 0.003171 0.004426 9.34e-05 0.000261 1.21e-06" />
          <geom type="mesh" mesh="HEAD" rgba="0.792156863 0.819607843 0.933333333 1" contype="0" conaffinity="0" group="1" />
        </body>
      </body>
    </body>
  </worldbody>
  
  <!-- Actuators for torque control -->
  <!-- Joint order matches robot_const.py: -->
  <!-- Right leg (0-5): HIP_YAW_R, HIP_ROLL_R, HIP_PITCH_R, KNEE_PITCH_R, ANKLE_PITCH_R, ANKLE_ROLL_R -->
  <!-- Left leg (6-11): HIP_YAW_L, HIP_ROLL_L, HIP_PITCH_L, KNEE_PITCH_L, ANKLE_PITCH_L, ANKLE_ROLL_L -->
  <!-- Right arm (12-18): SHOULDER_PITCH_R, SHOULDER_ROLL_R, SHOULDER_YAW_R, ELBOW_PITCH_R, ELBOW_YAW_R, WRIST_PITCH_R, WRIST_YAW_R -->
  <!-- Left arm (19-25): SHOULDER_PITCH_L, SHOULDER_ROLL_L, SHOULDER_YAW_L, ELBOW_PITCH_L, ELBOW_YAW_L, WRIST_PITCH_L, WRIST_YAW_L -->
  <!-- Head (26-27): HEAD_YAW, HEAD_PITCH -->
  <actuator>
    <!-- Right leg actuators -->
    <motor name="act_HIP_YAW_R" joint="HIP_YAW_R" ctrlrange="-100 100" ctrllimited="true" />
    <motor name="act_HIP_ROLL_R" joint="HIP_ROLL_R" ctrlrange="-100 100" ctrllimited="true" />
    <motor name="act_HIP_PITCH_R" joint="HIP_PITCH_R" ctrlrange="-100 100" ctrllimited="true" />
    <motor name="act_KNEE_PITCH_R" joint="KNEE_PITCH_R" ctrlrange="-100 100" ctrllimited="true" />
    <motor name="act_ANKLE_PITCH_R" joint="ANKLE_PITCH_R" ctrlrange="-100 100" ctrllimited="true" />
    <motor name="act_ANKLE_ROLL_R" joint="ANKLE_ROLL_R" ctrlrange="-100 100" ctrllimited="true" />
    
    <!-- Left leg actuators -->
    <motor name="act_HIP_YAW_L" joint="HIP_YAW_L" ctrlrange="-100 100" ctrllimited="true" />
    <motor name="act_HIP_ROLL_L" joint="HIP_ROLL_L" ctrlrange="-100 100" ctrllimited="true" />
    <motor name="act_HIP_PITCH_L" joint="HIP_PITCH_L" ctrlrange="-100 100" ctrllimited="true" />
    <motor name="act_KNEE_PITCH_L" joint="KNEE_PITCH_L" ctrlrange="-100 100" ctrllimited="true" />
    <motor name="act_ANKLE_PITCH_L" joint="ANKLE_PITCH_L" ctrlrange="-100 100" ctrllimited="true" />
    <motor name="act_ANKLE_ROLL_L" joint="ANKLE_ROLL_L" ctrlrange="-100 100" ctrllimited="true" />
    
    <!-- Right arm actuators -->
    <motor name="act_SHOULDER_PITCH_R" joint="SHOULDER_PITCH_R" ctrlrange="-30 30" ctrllimited="true" />
    <motor name="act_SHOULDER_ROLL_R" joint="SHOULDER_ROLL_R" ctrlrange="-30 30" ctrllimited="true" />
    <motor name="act_SHOULDER_YAW_R" joint="SHOULDER_YAW_R" ctrlrange="-30 30" ctrllimited="true" />
    <motor name="act_ELBOW_PITCH_R" joint="ELBOW_PITCH_R" ctrlrange="-30 30" ctrllimited="true" />
    <motor name="act_ELBOW_YAW_R" joint="ELBOW_YAW_R" ctrlrange="-30 30" ctrllimited="true" />
    <motor name="act_WRIST_PITCH_R" joint="WRIST_PITCH_R" ctrlrange="-10 10" ctrllimited="true" />
    <motor name="act_WRIST_YAW_R" joint="WRIST_YAW_R" ctrlrange="-10 10" ctrllimited="true" />
    
    <!-- Left arm actuators -->
    <motor name="act_SHOULDER_PITCH_L" joint="SHOULDER_PITCH_L" ctrlrange="-30 30" ctrllimited="true" />
    <motor name="act_SHOULDER_ROLL_L" joint="SHOULDER_ROLL_L" ctrlrange="-30 30" ctrllimited="true" />
    <motor name="act_SHOULDER_YAW_L" joint="SHOULDER_YAW_L" ctrlrange="-30 30" ctrllimited="true" />
    <motor name="act_ELBOW_PITCH_L" joint="ELBOW_PITCH_L" ctrlrange="-30 30" ctrllimited="true" />
    <motor name="act_ELBOW_YAW_L" joint="ELBOW_YAW_L" ctrlrange="-30 30" ctrllimited="true" />
    <motor name="act_WRIST_PITCH_L" joint="WRIST_PITCH_L" ctrlrange="-10 10" ctrllimited="true" />
    <motor name="act_WRIST_YAW_L" joint="WRIST_YAW_L" ctrlrange="-10 10" ctrllimited="true" />
    
    <!-- Head actuators -->
    <motor name="act_HEAD_YAW" joint="HEAD_YAW" ctrlrange="-10 10" ctrllimited="true" />
    <motor name="act_HEAD_PITCH" joint="HEAD_PITCH" ctrlrange="-10 10" ctrllimited="true" />
  </actuator>
</mujoco>
